<?xml version="1.0" ?>
<sdf version="1.8">
  <model name='vehicle_blue' canonical_link='chassis'>
    <!-- Lidar frame -->
    <frame name="lidar_frame" attached_to='chassis'>
      <pose>0.2 0 0.125 0 0 0</pose>
    </frame>

    <!-- Karosszéria -->
    <link name='chassis'>
      <pose relative_to='__model__'>0.125 0 0.1 0 0 0</pose>
      <inertial>
        <mass>1.14395</mass>
        <inertia>
          <ixx>0.095329</ixx>
          <ixy>0</ixy>
          <ixz>0</ixz>
          <iyy>0.381317</iyy>
          <iyz>0</iyz>
          <izz>0.476646</izz>
        </inertia>
      </inertial>
      <visual name='visual'>
        <geometry>
          <box>
            <size>0.5 0.25 0.125</size>
          </box>
        </geometry>
        <material>
          <ambient>0.0 0.0 1.0 1</ambient>
          <diffuse>0.0 0.0 1.0 1</diffuse>
          <specular>0.0 0.0 1.0 1</specular>
        </material>
      </visual>
      <collision name='collision'>
        <geometry>
          <box>
            <size>0.5 0.25 0.125</size>
          </box>
        </geometry>
      </collision>

      <!-- 2D LiDAR -->
      <sensor name='gpu_lidar' type='gpu_lidar'>
        <pose relative_to='lidar_frame'>0 0 0 0 0 0</pose>
        <topic>lidar</topic>
        <update_rate>10</update_rate>
        <ray>
          <scan>
            <horizontal>
              <samples>640</samples>
              <resolution>1</resolution>
              <min_angle>-1.396263</min_angle>
              <max_angle>1.396263</max_angle>
            </horizontal>
            <vertical>
              <samples>1</samples>
              <resolution>0.01</resolution>
              <min_angle>0</min_angle>
              <max_angle>0</max_angle>
            </vertical>
          </scan>
          <range>
            <min>0.08</min>
            <max>10.0</max>
            <resolution>0.01</resolution>
          </range>
        </ray>
        <alwaysOn>1</alwaysOn>
        <visualize>true</visualize>
      </sensor>

      <!-- IMU -->
      <sensor name="imu_sensor" type="imu">
        <pose>0 0 0 0 0 0</pose>
        <always_on>1</always_on>
        <update_rate>1</update_rate>
        <visualize>true</visualize>
        <topic>imu</topic>
      </sensor>
    </link>

    <!-- 3D LiDAR link és szenzor -->
    <link name='lidar_3d_link'>
      <pose relative_to='chassis'>0.2 0 0.25 0 0 0</pose>

      <sensor name='gpu_lidar_3d' type='gpu_lidar'>
        <pose>0 0 0 0 0 0</pose>
        <topic>lidar_3d_points</topic>
        <update_rate>10</update_rate>
        <ray>
          <scan>
            <horizontal>
              <samples>1024</samples>
              <resolution>1</resolution>
              <min_angle>-3.14159</min_angle>
              <max_angle>3.14159</max_angle>
            </horizontal>
            <vertical>
              <samples>16</samples>
              <resolution>1</resolution>
              <min_angle>-0.261799</min_angle>
              <max_angle>0.261799</max_angle>
            </vertical>
          </scan>
          <range>
            <min>0.1</min>
            <max>30.0</max>
            <resolution>0.01</resolution>
          </range>
        </ray>
        <alwaysOn>1</alwaysOn>
        <visualize>true</visualize>
      </sensor>
    </link>

    <!-- Bal kerék -->
    <link name='left_wheel'>
      <pose relative_to="chassis">-0.125 0.15 0 -1.5707 0 0</pose>
      <inertial>
        <mass>1</mass>
        <inertia>
          <ixx>0.043333</ixx>
          <iyy>0.043333</iyy>
          <izz>0.08</izz>
        </inertia>
      </inertial>
      <visual name='visual'>
        <geometry>
          <cylinder>
            <radius>0.1</radius>
            <length>0.05</length>
          </cylinder>
        </geometry>
        <material>
          <ambient>1.0 0.0 0.0 1</ambient>
          <diffuse>1.0 0.0 0.0 1</diffuse>
        </material>
      </visual>
      <collision name='collision'>
        <geometry>
          <cylinder>
            <radius>0.1</radius>
            <length>0.05</length>
          </cylinder>
        </geometry>
      </collision>
    </link>

    <!-- Jobb kerék -->
    <link name='right_wheel'>
      <pose relative_to="chassis">-0.125 -0.15 0 -1.5707 0 0</pose>
      <inertial>
        <mass>1</mass>
        <inertia>
          <ixx>0.043333</ixx>
          <iyy>0.043333</iyy>
          <izz>0.08</izz>
        </inertia>
      </inertial>
      <visual name='visual'>
        <geometry>
          <cylinder>
            <radius>0.1</radius>
            <length>0.05</length>
          </cylinder>
        </geometry>
        <material>
          <ambient>1.0 0.0 0.0 1</ambient>
          <diffuse>1.0 0.0 0.0 1</diffuse>
        </material>
      </visual>
      <collision name='collision'>
        <geometry>
          <cylinder>
            <radius>0.1</radius>
            <length>0.05</length>
          </cylinder>
        </geometry>
      </collision>
    </link>

    <!-- Támasztó görgő -->
    <frame name="caster_frame" attached_to='chassis'>
      <pose>0.2 0 -0.05 0 0 0</pose>
    </frame>

    <link name='caster'>
      <pose relative_to='caster_frame'/>
      <inertial>
        <mass>1</mass>
        <inertia>
          <ixx>0.016</ixx>
          <iyy>0.016</iyy>
          <izz>0.016</izz>
        </inertia>
      </inertial>
      <visual name='visual'>
        <geometry>
          <sphere>
            <radius>0.05</radius>
          </sphere>
        </geometry>
        <material>
          <ambient>0.0 1.0 0.0 1</ambient>
          <diffuse>0.0 1.0 0.0 1</diffuse>
        </material>
      </visual>
      <collision name='collision'>
        <geometry>
          <sphere>
            <radius>0.05</radius>
          </sphere>
        </geometry>
      </collision>
    </link>

    <!-- Jointok -->
    <joint name='left_wheel_joint' type='revolute'>
      <pose relative_to='left_wheel'/>
      <parent>chassis</parent>
      <child>left_wheel</child>
      <axis>
        <xyz expressed_in='__model__'>0 1 0</xyz>
      </axis>
    </joint>

    <joint name='right_wheel_joint' type='revolute'>
      <pose relative_to='right_wheel'/>
      <parent>chassis</parent>
      <child>right_wheel</child>
      <axis>
        <xyz expressed_in='__model__'>0 1 0</xyz>
      </axis>
    </joint>

    <joint name='caster_wheel' type='ball'>
      <parent>chassis</parent>
      <child>caster</child>
    </joint>

    <!-- DiffDrive plugin -->
    <plugin
      filename="libignition-gazebo-diff-drive-system.so"
      name="ignition::gazebo::systems::DiffDrive">
      <left_joint>left_wheel_joint</left_joint>
      <right_joint>right_wheel_joint</right_joint>
      <wheel_separation>0.3</wheel_separation>
      <wheel_radius>0.1</wheel_radius>

      <odom_frame>odom</odom_frame>
      <odom_publish_frequency>30</odom_publish_frequency>
      <odometry_topic>odom</odometry_topic>

      <frame_id>odom</frame_id>
      <child_frame_id>chassis</child_frame_id>

      <publish_odom>true</publish_odom>
      <publish_odom_tf>true</publish_odom_tf>

      <topic>cmd_vel</topic>
    </plugin>
  </model>
</sdf>
